- what about the 'Error on stream: RTSPConnectionError('RTSP connection lost: [Errno 104] Connection reset by peer'). Reconnecting...'
error?

Task exception was never retrieved
future: <Task finished coro=<RTPTransport.timeout_loop() done, defined at /Library/Frameworks/Python.framework/Versions/3.7/lib/python3.7/site-packages/aiortsp/transport/base.py:147> exception=CancelledError()>
concurrent.futures._base.CancelledError